Workbook

Sheet Cover
B1: [COMPANY NAME] — INVESTOR DCF MODEL
B2: Company | C2: [Company Name]
B3: Technology / Product | C3: [Core Technology or Product]
B4: Business Model | C4: [e.g. Licensing | Royalties | Milestones]
B5: Model Version | C5: v1.0
B6: Projection Period | C6: [YYYY] - [YYYY]
B7: Valuation Date | C7: [Month Year]
B8: Prepared by | C8: [Analyst Name]
B9: WACC (Base) | C9: see Assumptions sheet
B10: Terminal Growth | C10: see Assumptions sheet
B12: COLOR LEGEND
B13: Blue text | C13: Hardcoded input assumptions — editable by founder
B14: Black text | C14: Calculated formulas — do not edit
B15: Green text | C15: Cross-sheet links — do not edit
B16: Yellow fill | C16: Cells requiring attention or confirmation
B17: Emoji in notes col | C17: See column M for guidance on each input

Sheet Assumptions
B1: [COMPANY NAME] — DCF MODEL | ASSUMPTIONS
B2: CHF | C2: 2025 | D2: 2026 | E2: 2027 | F2: 2028 | G2: 2029 | H2: 2030 | I2: 2031 | J2: 2032 | K2: 2033 | L2: 2034 | M2: 2035 | N2: Source / Note
B3: A. MACRO & DISCOUNT RATE
B4: Risk-Free Rate (10Y CHF Govt) | N4: 📌 Insert: current 10Y risk-free rate for your currency (e.g. SNB, Fed, ECB)
B5: Equity Risk Premium | N5: 📌 Insert: Equity Risk Premium — see Damodaran online (damodaran.com → Risk Premiums)
B6: Beta (unlevered, Biotech/Nutr.) | N6: 📌 Insert: unlevered beta for your sector — Damodaran sector beta table, select closest industry
B7: Cost of Equity (CAPM) | C7: =C4+C6*C5 -> 0 | D7: =D4+D6*D5 -> 0 | E7: =E4+E6*E5 -> 0 | F7: =F4+F6*F5 -> 0 | G7: =G4+G6*G5 -> 0 | H7: =H4+H6*H5 -> 0 | I7: =I4+I6*I5 -> 0 | J7: =J4+J6*J5 -> 0 | ... M7: =M4+M6*M5 -> 0 | N7: CAPM: Ke = Rf + β × ERP
B8: Cost of Debt (pre-tax) | N8: 📌 Insert: cost of debt — use interest rate on your CLA / loan, or market rate for early-stage
B9: Tax Rate | N9: 📌 Insert: effective corporate tax rate for your jurisdiction (canton + federal, or country rate)
B10: Debt / (Debt+Equity) | N10: 📌 Insert: target D/(D+E) ratio — for early-stage startups typically 0–20%
B11: WACC | C11: =C7*(1-C10)+C8*(1-C9)*C10 -> 0 | D11: =D7*(1-D10)+D8*(1-D9)*D10 -> 0 | E11: =E7*(1-E10)+E8*(1-E9)*E10 -> 0 | F11: =F7*(1-F10)+F8*(1-F9)*F10 -> 0 | G11: =G7*(1-G10)+G8*(1-G9)*G10 -> 0 | H11: =H7*(1-H10)+H8*(1-H9)*H10 -> 0 | I11: =I7*(1-I10)+I8*(1-I9)*I10 -> 0 | J11: =J7*(1-J10)+J8*(1-J9)*J10 -> 0 | ... M11: =M7*(1-M10)+M8*(1-M9)*M10 -> 0 | N11: WACC = Ke×(1-D/V) + Kd×(1-t)×(D/V); bottom-up CAPM
B13: B. REVENUE ASSUMPTIONS — DEAL STRUCTURE
B14: Deal 1 — [Partner Name / Deal Description]
B15: Deal 1: Contract Signing Year | N15: 📌 Insert: year deal is signed — upfront license fee recognised in this year
B16: Deal 1: Upfront License Fee (CHF) | N16: 📌 Insert: upfront license fee agreed with partner — check comparable deals in your sector
B17: Deal 1: Royalty Rate | N17: 📌 Insert: royalty rate negotiated with partner — typical range 2–10% depending on IP strength & sector
B18: Deal 1: Partner Revenue Base (CHF) | N18: 📌 Insert: partner's projected revenue base year-by-year — use partner's own forecasts or market data
B19: Deal 1: Royalty Revenue | C19: =IFERROR(C18*C17,0) -> 0 | D19: =IFERROR(D18*D17,0) -> 0 | E19: =IFERROR(E18*E17,0) -> 0 | F19: =IFERROR(F18*F17,0) -> 0 | G19: =IFERROR(G18*G17,0) -> 0 | H19: =IFERROR(H18*H17,0) -> 0 | I19: =IFERROR(I18*I17,0) -> 0 | J19: =IFERROR(J18*J17,0) -> 0 | ... M19: =IFERROR(M18*M17,0) -> 0 | N19: ℹ️ Formula auto-calculated: Partner Revenue Base × Royalty Rate
B21: Deal 2 — [Partner Name / Deal Description]
B22: Deal 2: Co-Dev Fee Start Year | N22: 📌 Insert: year co-development agreement starts — fee recognised from this year
B23: Deal 2: Annual Co-Dev Fee (CHF) | N23: 📌 Insert: annual co-development fee agreed with partner — fill only the years the agreement is active
B24: Deal 2: Royalty Rate | N24: 📌 Insert: royalty rate for this deal — may differ from Deal 1 based on partner contribution
B25: Deal 2: Partner Revenue Base (CHF) | N25: 📌 Insert: partner's revenue base from which royalties are calculated — fill from commercial launch year
B26: Deal 2: Royalty Revenue | C26: =IFERROR(C25*C24,0) -> 0 | D26: =IFERROR(D25*D24,0) -> 0 | E26: =IFERROR(E25*E24,0) -> 0 | F26: =IFERROR(F25*F24,0) -> 0 | G26: =IFERROR(G25*G24,0) -> 0 | H26: =IFERROR(H25*H24,0) -> 0 | I26: =IFERROR(I25*I24,0) -> 0 | J26: =IFERROR(J25*J24,0) -> 0 | ... M26: =IFERROR(M25*M24,0) -> 0 | N26: ℹ️ Formula auto-calculated: Partner Revenue Base × Royalty Rate
B28: Deals 3–6 — Placeholder (Additional Partners)
B29: Deal 3: Annual Revenue (CHF) | N29: 📌 Insert: total annual revenue from this deal (upfront + fees + royalties combined)
B30: Deal 4: Annual Revenue (CHF) | N30: 📌 Insert: total annual revenue from this deal (upfront + fees + royalties combined)
B31: Deal 5: Annual Revenue (CHF) | N31: 📌 Insert: total annual revenue from this deal — leave blank if not applicable
B32: Deal 6: Annual Revenue (CHF) | N32: 📌 Insert: total annual revenue from this deal — leave blank if not applicable
B34: C. OPEX ASSUMPTIONS
B35: Personnel — FTEs | N35: 📌 Insert: number of full-time employees (FTEs) per year — include founders
B36: Avg. Fully-Loaded Cost / FTE (CHF) | N36: 📌 Insert: average fully-loaded cost per FTE — include salary + employer social charges + benefits
B37: Lab & Materials (CHF) | N37: 📌 Insert: annual lab & materials cost — include consumables, reagents, lab access fees
B38: IP / Patent Maintenance (CHF) | N38: 📌 Insert: IP & patent costs — include filing fees, renewal fees, patent attorney retainer
B39: Regulatory & Clinical (CHF) | N39: 📌 Insert: regulatory & clinical costs — typically higher in early years during approval process
B40: G&A / Facilities (CHF) | N40: 📌 Insert: G&A costs — office rent, insurance, legal, accounting, admin
B41: CPI Escalator | N41: 📌 Insert: annual cost inflation rate — used to escalate personnel costs over time (e.g. 1.5–2.5%)
B43: D. CAPEX & NET WORKING CAPITAL
B44: Capex — Lab Equipment (CHF) | N44: 📌 Insert: annual capex — lab equipment purchases, IT, any physical assets. 0 if fully asset-light
B45: D&A Rate on Gross PP&E | N45: 📌 Insert: D&A rate — 20% = 5yr straight-line life. Adjust based on your asset types
...

Sheet Revenue
B1: REVENUE FORECAST (CHF)
C2: 2025 | D2: 2026 | E2: 2027 | F2: 2028 | G2: 2029 | H2: 2030 | I2: 2031 | J2: 2032 | K2: 2033 | L2: 2034 | M2: 2035
B3: LICENSING & ROYALTY REVENUE BY DEAL
B4: Deal 1 — Upfront + Royalty Revenue | C4: =Assumptions!C16+Assumptions!C19 -> 0 | D4: =Assumptions!D19 -> 0 | E4: =Assumptions!E19 -> 0 | F4: =Assumptions!F19 -> 0 | G4: =Assumptions!G19 -> 0 | H4: =Assumptions!H19 -> 0 | I4: =Assumptions!I19 -> 0 | J4: =Assumptions!J19 -> 0 | K4: =Assumptions!K19 -> 0 | ... M4: =Assumptions!M19 -> 0
B5: Deal 2 — Co-Dev Fees + Royalty Revenue | C5: =IFERROR(Assumptions!C26,0) -> 0 | D5: =IFERROR(Assumptions!D26,0) -> 0 | E5: =IFERROR(Assumptions!E26,0) -> 0 | F5: =IFERROR(Assumptions!F23,0)+IFERROR(Assumptions!F26,0) -> 0 | G5: =IFERROR(Assumptions!G23,0)+IFERROR(Assumptions!G26,0) -> 0 | H5: =IFERROR(Assumptions!H23,0)+IFERROR(Assumptions!H26,0) -> 0 | I5: =IFERROR(Assumptions!I26,0) -> 0 | J5: =IFERROR(Assumptions!J26,0) -> 0 | K5: =IFERROR(Assumptions!K26,0) -> 0 | L5: =IFERROR(Assumptions!L26,0) -> 0 | M5: =IFERROR(Assumptions!M26,0) -> 0
B6: Deal 3 — Revenue | C6: =IFERROR(Assumptions!C29,0) -> 0 | D6: =IFERROR(Assumptions!D29,0) -> 0 | E6: =IFERROR(Assumptions!E29,0) -> 0 | F6: =IFERROR(Assumptions!F29,0) -> 0 | G6: =IFERROR(Assumptions!G29,0) -> 0 | H6: =IFERROR(Assumptions!H29,0) -> 0 | I6: =IFERROR(Assumptions!I29,0) -> 0 | J6: =IFERROR(Assumptions!J29,0) -> 0 | ... M6: =IFERROR(Assumptions!M29,0) -> 0
B7: Deal 4 — Revenue | C7: =IFERROR(Assumptions!C30,0) -> 0 | D7: =IFERROR(Assumptions!D30,0) -> 0 | E7: =IFERROR(Assumptions!E30,0) -> 0 | F7: =IFERROR(Assumptions!F30,0) -> 0 | G7: =IFERROR(Assumptions!G30,0) -> 0 | H7: =IFERROR(Assumptions!H30,0) -> 0 | I7: =IFERROR(Assumptions!I30,0) -> 0 | J7: =IFERROR(Assumptions!J30,0) -> 0 | ... M7: =IFERROR(Assumptions!M30,0) -> 0
B8: Deal 5 — Revenue | C8: =IFERROR(Assumptions!C31,0) -> 0 | D8: =IFERROR(Assumptions!D31,0) -> 0 | E8: =IFERROR(Assumptions!E31,0) -> 0 | F8: =IFERROR(Assumptions!F31,0) -> 0 | G8: =IFERROR(Assumptions!G31,0) -> 0 | H8: =IFERROR(Assumptions!H31,0) -> 0 | I8: =IFERROR(Assumptions!I31,0) -> 0 | J8: =IFERROR(Assumptions!J31,0) -> 0 | ... M8: =IFERROR(Assumptions!M31,0) -> 0
B9: Deal 6 — Revenue | C9: =IFERROR(Assumptions!C32,0) -> 0 | D9: =IFERROR(Assumptions!D32,0) -> 0 | E9: =IFERROR(Assumptions!E32,0) -> 0 | F9: =IFERROR(Assumptions!F32,0) -> 0 | G9: =IFERROR(Assumptions!G32,0) -> 0 | H9: =IFERROR(Assumptions!H32,0) -> 0 | I9: =IFERROR(Assumptions!I32,0) -> 0 | J9: =IFERROR(Assumptions!J32,0) -> 0 | ... M9: =IFERROR(Assumptions!M32,0) -> 0
B11: TOTAL REVENUE | C11: =SUM(C4,C5,C6,C7,C8,C9) -> 0 | D11: =SUM(D4,D5,D6,D7,D8,D9) -> 0 | E11: =SUM(E4,E5,E6,E7,E8,E9) -> 0 | F11: =SUM(F4,F5,F6,F7,F8,F9) -> 0 | G11: =SUM(G4,G5,G6,G7,G8,G9) -> 0 | H11: =SUM(H4,H5,H6,H7,H8,H9) -> 0 | I11: =SUM(I4,I5,I6,I7,I8,I9) -> 0 | J11: =SUM(J4,J5,J6,J7,J8,J9) -> 0 | ... M11: =SUM(M4,M5,M6,M7,M8,M9) -> 0
B13: REVENUE BRIDGE BY TYPE
B14: Upfront License Fees | C14: =IF(C2=2025,Assumptions!C16,0) -> 0 | D14: =IF(D2=2025,Assumptions!D16,0) -> 0 | E14: =IF(E2=2025,Assumptions!E16,0) -> 0 | F14: =IF(F2=2025,Assumptions!F16,0) -> 0 | G14: =IF(G2=2025,Assumptions!G16,0) -> 0 | H14: =IF(H2=2025,Assumptions!H16,0) -> 0 | I14: =IF(I2=2025,Assumptions!I16,0) -> 0 | J14: =IF(J2=2025,Assumptions!J16,0) -> 0 | ... M14: =IF(M2=2025,Assumptions!M16,0) -> 0
B15: Co-Development Fees | C15: =IFERROR(Assumptions!C23,0) -> 0 | D15: =IFERROR(Assumptions!D23,0) -> 0 | E15: =IFERROR(Assumptions!E23,0) -> 0 | F15: =IFERROR(Assumptions!F23,0) -> 0 | G15: =IFERROR(Assumptions!G23,0) -> 0 | H15: =IFERROR(Assumptions!H23,0) -> 0 | I15: =IFERROR(Assumptions!I23,0) -> 0 | J15: =IFERROR(Assumptions!J23,0) -> 0 | ... M15: =IFERROR(Assumptions!M23,0) -> 0
B16: Royalties (ongoing) | C16: =IFERROR(Assumptions!C19,0)+IFERROR(Assumptions!C26,0) -> 0 | D16: =IFERROR(Assumptions!D19,0)+IFERROR(Assumptions!D26,0) -> 0 | E16: =IFERROR(Assumptions!E19,0)+IFERROR(Assumptions!E26,0) -> 0 | F16: =IFERROR(Assumptions!F19,0)+IFERROR(Assumptions!F26,0) -> 0 | G16: =IFERROR(Assumptions!G19,0)+IFERROR(Assumptions!G26,0) -> 0 | H16: =IFERROR(Assumptions!H19,0)+IFERROR(Assumptions!H26,0) -> 0 | I16: =IFERROR(Assumptions!I19,0)+IFERROR(Assumptions!I26,0) -> 0 | J16: =IFERROR(Assumptions!J19,0)+IFERROR(Assumptions!J26,0) -> 0 | ... M16: =IFERROR(Assumptions!M19,0)+IFERROR(Assumptions!M26,0) -> 0
B18: Revenue Growth YoY | C18: - | D18: =IFERROR((D11-C11)/C11,"-") -> - | E18: =IFERROR((E11-D11)/D11,"-") -> - | F18: =IFERROR((F11-E11)/E11,"-") -> - | G18: =IFERROR((G11-F11)/F11,"-") -> - | H18: =IFERROR((H11-G11)/G11,"-") -> - | I18: =IFERROR((I11-H11)/H11,"-") -> - | J18: =IFERROR((J11-I11)/I11,"-") -> - | K18: =IFERROR((K11-J11)/J11,"-") -> - | ... M18: =IFERROR((M11-L11)/L11,"-") -> -

Sheet PnL_OPEX
B1: P&L — OPERATING EXPENSES & EBITDA
C2: 2025 | D2: 2026 | E2: 2027 | F2: 2028 | G2: 2029 | H2: 2030 | I2: 2031 | J2: 2032 | K2: 2033 | L2: 2034 | M2: 2035
B3: REVENUE (LINKED)
B4: Total Revenue | C4: =Revenue!C11 -> 0 | D4: =Revenue!D11 -> 0 | E4: =Revenue!E11 -> 0 | F4: =Revenue!F11 -> 0 | G4: =Revenue!G11 -> 0 | H4: =Revenue!H11 -> 0 | I4: =Revenue!I11 -> 0 | J4: =Revenue!J11 -> 0 | ... M4: =Revenue!M11 -> 0
B6: OPERATING EXPENSES
B7: Personnel Costs | C7: =Assumptions!C35*Assumptions!C36*(1+Assumptions!C41)^(0) -> 0 | D7: =Assumptions!D35*Assumptions!D36*(1+Assumptions!D41)^(1) -> 0 | E7: =Assumptions!E35*Assumptions!E36*(1+Assumptions!E41)^(2) -> 0 | F7: =Assumptions!F35*Assumptions!F36*(1+Assumptions!F41)^(3) -> 0 | G7: =Assumptions!G35*Assumptions!G36*(1+Assumptions!G41)^(4) -> 0 | H7: =Assumptions!H35*Assumptions!H36*(1+Assumptions!H41)^(5) -> 0 | I7: =Assumptions!I35*Assumptions!I36*(1+Assumptions!I41)^(6) -> 0 | J7: =Assumptions!J35*Assumptions!J36*(1+Assumptions!J41)^(7) -> 0 | K7: =Assumptions!K35*Assumptions!K36*(1+Assumptions!K41)^(8) -> 0 | L7: =Assumptions!L35*Assumptions!L36*(1+Assumptions!L41)^(9) -> 0 | M7: =Assumptions!M35*Assumptions!M36*(1+Assumptions!M41)^(10) -> 0
B8: Lab & Materials | C8: =Assumptions!C37 -> 0 | D8: =Assumptions!D37 -> 0 | E8: =Assumptions!E37 -> 0 | F8: =Assumptions!F37 -> 0 | G8: =Assumptions!G37 -> 0 | H8: =Assumptions!H37 -> 0 | I8: =Assumptions!I37 -> 0 | J8: =Assumptions!J37 -> 0 | ... M8: =Assumptions!M37 -> 0
B9: IP / Patent Costs | C9: =Assumptions!C38 -> 0 | D9: =Assumptions!D38 -> 0 | E9: =Assumptions!E38 -> 0 | F9: =Assumptions!F38 -> 0 | G9: =Assumptions!G38 -> 0 | H9: =Assumptions!H38 -> 0 | I9: =Assumptions!I38 -> 0 | J9: =Assumptions!J38 -> 0 | ... M9: =Assumptions!M38 -> 0
B10: Regulatory & Clinical | C10: =Assumptions!C39 -> 0 | D10: =Assumptions!D39 -> 0 | E10: =Assumptions!E39 -> 0 | F10: =Assumptions!F39 -> 0 | G10: =Assumptions!G39 -> 0 | H10: =Assumptions!H39 -> 0 | I10: =Assumptions!I39 -> 0 | J10: =Assumptions!J39 -> 0 | ... M10: =Assumptions!M39 -> 0
B11: G&A / Facilities | C11: =Assumptions!C40 -> 0 | D11: =Assumptions!D40 -> 0 | E11: =Assumptions!E40 -> 0 | F11: =Assumptions!F40 -> 0 | G11: =Assumptions!G40 -> 0 | H11: =Assumptions!H40 -> 0 | I11: =Assumptions!I40 -> 0 | J11: =Assumptions!J40 -> 0 | ... M11: =Assumptions!M40 -> 0
B12: Total OPEX | C12: =SUM(C7,C8,C9,C10,C11) -> 0 | D12: =SUM(D7,D8,D9,D10,D11) -> 0 | E12: =SUM(E7,E8,E9,E10,E11) -> 0 | F12: =SUM(F7,F8,F9,F10,F11) -> 0 | G12: =SUM(G7,G8,G9,G10,G11) -> 0 | H12: =SUM(H7,H8,H9,H10,H11) -> 0 | I12: =SUM(I7,I8,I9,I10,I11) -> 0 | J12: =SUM(J7,J8,J9,J10,J11) -> 0 | ... M12: =SUM(M7,M8,M9,M10,M11) -> 0
B14: EBITDA
B15: EBITDA | C15: =C4-C12 -> 0 | D15: =D4-D12 -> 0 | E15: =E4-E12 -> 0 | F15: =F4-F12 -> 0 | G15: =G4-G12 -> 0 | H15: =H4-H12 -> 0 | I15: =I4-I12 -> 0 | J15: =J4-J12 -> 0 | ... M15: =M4-M12 -> 0
B16: EBITDA Margin % | C16: =IFERROR(C15/C4,"-") -> - | D16: =IFERROR(D15/D4,"-") -> - | E16: =IFERROR(E15/E4,"-") -> - | F16: =IFERROR(F15/F4,"-") -> - | G16: =IFERROR(G15/G4,"-") -> - | H16: =IFERROR(H15/H4,"-") -> - | I16: =IFERROR(I15/I4,"-") -> - | J16: =IFERROR(J15/J4,"-") -> - | ... M16: =IFERROR(M15/M4,"-") -> -
B18: D&A & EBIT
B19: Depreciation & Amortization | C19: =Assumptions!C45*SUM(Assumptions!C44:C44) -> 0 | D19: =Assumptions!D45*SUM(Assumptions!C44:D44) -> 0 | E19: =Assumptions!E45*SUM(Assumptions!C44:E44) -> 0 | F19: =Assumptions!F45*SUM(Assumptions!C44:F44) -> 0 | G19: =Assumptions!G45*SUM(Assumptions!C44:G44) -> 0 | H19: =Assumptions!H45*SUM(Assumptions!C44:H44) -> 0 | I19: =Assumptions!I45*SUM(Assumptions!C44:I44) -> 0 | J19: =Assumptions!J45*SUM(Assumptions!C44:J44) -> 0 | K19: =Assumptions!K45*SUM(Assumptions!C44:K44) -> 0 | L19: =Assumptions!L45*SUM(Assumptions!C44:L44) -> 0 | M19: =Assumptions!M45*SUM(Assumptions!C44:M44) -> 0
B20: EBIT | C20: =C15-C19 -> 0 | D20: =D15-D19 -> 0 | E20: =E15-E19 -> 0 | F20: =F15-F19 -> 0 | G20: =G15-G19 -> 0 | H20: =H15-H19 -> 0 | I20: =I15-I19 -> 0 | J20: =J15-J19 -> 0 | ... M20: =M15-M19 -> 0
B21: Taxes (EBIT × Tax Rate) | C21: =MAX(0,C20)*Assumptions!C9 -> 0 | D21: =MAX(0,D20)*Assumptions!D9 -> 0 | E21: =MAX(0,E20)*Assumptions!E9 -> 0 | F21: =MAX(0,F20)*Assumptions!F9 -> 0 | G21: =MAX(0,G20)*Assumptions!G9 -> 0 | H21: =MAX(0,H20)*Assumptions!H9 -> 0 | I21: =MAX(0,I20)*Assumptions!I9 -> 0 | J21: =MAX(0,J20)*Assumptions!J9 -> 0 | ... M21: =MAX(0,M20)*Assumptions!M9 -> 0
B22: NOPAT (= EBIT × (1−t)) | C22: =C20-C21 -> 0 | D22: =D20-D21 -> 0 | E22: =E20-E21 -> 0 | F22: =F20-F21 -> 0 | G22: =G20-G21 -> 0 | H22: =H20-H21 -> 0 | I22: =I20-I21 -> 0 | J22: =J20-J21 -> 0 | ... M22: =M20-M21 -> 0

Sheet FCF_DCF
B1: FREE CASH FLOW TO FIRM & DCF VALUATION
C2: 2025 | D2: 2026 | E2: 2027 | F2: 2028 | G2: 2029 | H2: 2030 | I2: 2031 | J2: 2032 | K2: 2033 | L2: 2034 | M2: 2035
B3: FCF BRIDGE (NOPAT → FCFF)
B4: NOPAT | C4: =PnL_OPEX!C22 -> 0 | D4: =PnL_OPEX!D22 -> 0 | E4: =PnL_OPEX!E22 -> 0 | F4: =PnL_OPEX!F22 -> 0 | G4: =PnL_OPEX!G22 -> 0 | H4: =PnL_OPEX!H22 -> 0 | I4: =PnL_OPEX!I22 -> 0 | J4: =PnL_OPEX!J22 -> 0 | ... M4: =PnL_OPEX!M22 -> 0
B5: (+) Depreciation & Amortization | C5: =PnL_OPEX!C19 -> 0 | D5: =PnL_OPEX!D19 -> 0 | E5: =PnL_OPEX!E19 -> 0 | F5: =PnL_OPEX!F19 -> 0 | G5: =PnL_OPEX!G19 -> 0 | H5: =PnL_OPEX!H19 -> 0 | I5: =PnL_OPEX!I19 -> 0 | J5: =PnL_OPEX!J19 -> 0 | ... M5: =PnL_OPEX!M19 -> 0
B6: (−) Capital Expenditures | C6: =-Assumptions!C44 -> 0 | D6: =-Assumptions!D44 -> 0 | E6: =-Assumptions!E44 -> 0 | F6: =-Assumptions!F44 -> 0 | G6: =-Assumptions!G44 -> 0 | H6: =-Assumptions!H44 -> 0 | I6: =-Assumptions!I44 -> 0 | J6: =-Assumptions!J44 -> 0 | ... M6: =-Assumptions!M44 -> 0
B7: (−) Change in Net Working Capital | C7: =0 -> 0 | D7: =-(Assumptions!D46*Revenue!D11-Assumptions!C46*Revenue!C11) -> 0 | E7: =-(Assumptions!E46*Revenue!E11-Assumptions!D46*Revenue!D11) -> 0 | F7: =-(Assumptions!F46*Revenue!F11-Assumptions!E46*Revenue!E11) -> 0 | G7: =-(Assumptions!G46*Revenue!G11-Assumptions!F46*Revenue!F11) -> 0 | H7: =-(Assumptions!H46*Revenue!H11-Assumptions!G46*Revenue!G11) -> 0 | I7: =-(Assumptions!I46*Revenue!I11-Assumptions!H46*Revenue!H11) -> 0 | J7: =-(Assumptions!J46*Revenue!J11-Assumptions!I46*Revenue!I11) -> 0 | K7: =-(Assumptions!K46*Revenue!K11-Assumptions!J46*Revenue!J11) -> 0 | ... M7: =-(Assumptions!M46*Revenue!M11-Assumptions!L46*Revenue!L11) -> 0
B8: FCFF | C8: =C4+C5+C6+C7 -> 0 | D8: =D4+D5+D6+D7 -> 0 | E8: =E4+E5+E6+E7 -> 0 | F8: =F4+F5+F6+F7 -> 0 | G8: =G4+G5+G6+G7 -> 0 | H8: =H4+H5+H6+H7 -> 0 | I8: =I4+I5+I6+I7 -> 0 | J8: =J4+J5+J6+J7 -> 0 | ... M8: =M4+M5+M6+M7 -> 0
B10: DISCOUNT FACTORS & PV(FCFF)
B11: Discount Factor | C11: =1/(1+Assumptions!C11)^0.5 -> 1 | D11: =1/(1+Assumptions!D11)^1.5 -> 1 | E11: =1/(1+Assumptions!E11)^2.5 -> 1 | F11: =1/(1+Assumptions!F11)^3.5 -> 1 | G11: =1/(1+Assumptions!G11)^4.5 -> 1 | H11: =1/(1+Assumptions!H11)^5.5 -> 1 | I11: =1/(1+Assumptions!I11)^6.5 -> 1 | J11: =1/(1+Assumptions!J11)^7.5 -> 1 | K11: =1/(1+Assumptions!K11)^8.5 -> 1 | L11: =1/(1+Assumptions!L11)^9.5 -> 1 | M11: =1/(1+Assumptions!M11)^10.5 -> 1
B12: PV of FCFF | C12: =C8*C11 -> 0 | D12: =D8*D11 -> 0 | E12: =E8*E11 -> 0 | F12: =F8*F11 -> 0 | G12: =G8*G11 -> 0 | H12: =H8*H11 -> 0 | I12: =I8*I11 -> 0 | J12: =J8*J11 -> 0 | ... M12: =M8*M11 -> 0
B14: TERMINAL VALUE (GORDON GROWTH MODEL)
B15: Terminal Value (nominal) — GGM | C15: - | D15: - | E15: - | F15: - | G15: - | H15: - | I15: - | J15: - | K15: - | L15: - | M15: =IFERROR(M8*(1+Assumptions!M49)/(Assumptions!M11-Assumptions!M49),"-") -> -
B16: PV of Terminal Value | C16: - | D16: - | E16: - | F16: - | G16: - | H16: - | I16: - | J16: - | K16: - | L16: - | M16: =IFERROR(M15*M11,"-") -> -
B18: ENTERPRISE VALUE & EQUITY BRIDGE
B19: Sum of PV(FCFF) | C19: =SUM(C12,D12,E12,F12,G12,H12,I12,J12,K12,L12,M12) -> 0
B20: Enterprise Value (EV) | C20: =IFERROR(C19+M16,"-") -> -
B21: (−) Net Debt (CLA outstanding)
B22: Equity Value | C22: =IFERROR(C20-C21,"-") -> -
B23: EV/EBITDA Cross-Check (2035) | C23: =IFERROR(C20/M15,"-") -> -

Sheet Scenarios
B1: SCENARIO ANALYSIS — BEAR / BASE / BULL
B3: Parameter | C3: Bear | D3: Base | E3: Bull | F3: Bear EV | G3: Base EV | H3: Bull EV
B4: Royalty Rate — Deal 1 | F4: — | G4: — | H4: —
B5: Co-Dev Fee — Deal 2 (CHF) | F5: — | G5: — | H5: —
B6: Nr. of Deals by 2030 | F6: — | G6: — | H6: —
B7: WACC | F7: — | G7: — | H7: —
B8: Long-Term Growth Rate (g) | F8: — | G8: — | H8: —
B9: Terminal EV/EBITDA | F9: — | G9: — | H9: —
B11: NOTE: Bear/Bull EV outputs require manual scenario toggle on Assumptions sheet. Dynamic engine TBD.

Sheet Sensitivity
B1: SENSITIVITY HEATMAP — EV (CHF '000)
B3: WACC \ g → | C3: 1.5% | D3: 2.0% | E3: 2.5% | F3: 3.0% | G3: 3.5%
B4: 18.0% | C4: =IFERROR(IF(VALUE($B4)<=VALUE(C$3),"-",(SUM(FCF_DCF!C8/(1+VALUE($B4))^0.5,FCF_DCF!D8/(1+VALUE($B4))^1.5,FCF_DCF!E8/(1+VALUE($B4))^2.5,FCF_DCF!F8/(1+VALUE($B4))^3.5,FCF_DCF!G8/(1+VALUE($B4))^4.5,FCF_DCF!H8/(1+VALUE($B4))^5.5,FCF_DCF!I8/(1+VALUE($B4))^6.5,FCF_DCF!J8/(1+VALUE($B4))^7.5,FCF_DCF!K8/(1+VALUE($B4))^8.5,FCF_DCF!L8/(1+VALUE($B4))^9.5,FCF_DCF!M8/(1+VALUE($B4))^10.5)+(FCF_DCF!M8*(1+VALUE(C$3))/(VALUE($B4)-VALUE(C$3)))/(1+VALUE($B4))^10.5)/1000),"-") -> - | D4: =IFERROR(IF(VALUE($B4)<=VALUE(D$3),"-",(SUM(FCF_DCF!C8/(1+VALUE($B4))^0.5,FCF_DCF!D8/(1+VALUE($B4))^1.5,FCF_DCF!E8/(1+VALUE($B4))^2.5,FCF_DCF!F8/(1+VALUE($B4))^3.5,FCF_DCF!G8/(1+VALUE($B4))^4.5,FCF_DCF!H8/(1+VALUE($B4))^5.5,FCF_DCF!I8/(1+VALUE($B4))^6.5,FCF_DCF!J8/(1+VALUE($B4))^7.5,FCF_DCF!K8/(1+VALUE($B4))^8.5,FCF_DCF!L8/(1+VALUE($B4))^9.5,FCF_DCF!M8/(1+VALUE($B4))^10.5)+(FCF_DCF!M8*(1+VALUE(D$3))/(VALUE($B4)-VALUE(D$3)))/(1+VALUE($B4))^10.5)/1000),"-") -> - | E4: =IFERROR(IF(VALUE($B4)<=VALUE(E$3),"-",(SUM(FCF_DCF!C8/(1+VALUE($B4))^0.5,FCF_DCF!D8/(1+VALUE($B4))^1.5,FCF_DCF!E8/(1+VALUE($B4))^2.5,FCF_DCF!F8/(1+VALUE($B4))^3.5,FCF_DCF!G8/(1+VALUE($B4))^4.5,FCF_DCF!H8/(1+VALUE($B4))^5.5,FCF_DCF!I8/(1+VALUE($B4))^6.5,FCF_DCF!J8/(1+VALUE($B4))^7.5,FCF_DCF!K8/(1+VALUE($B4))^8.5,FCF_DCF!L8/(1+VALUE($B4))^9.5,FCF_DCF!M8/(1+VALUE($B4))^10.5)+(FCF_DCF!M8*(1+VALUE(E$3))/(VALUE($B4)-VALUE(E$3)))/(1+VALUE($B4))^10.5)/1000),"-") -> - | F4: =IFERROR(IF(VALUE($B4)<=VALUE(F$3),"-",(SUM(FCF_DCF!C8/(1+VALUE($B4))^0.5,FCF_DCF!D8/(1+VALUE($B4))^1.5,FCF_DCF!E8/(1+VALUE($B4))^2.5,FCF_DCF!F8/(1+VALUE($B4))^3.5,FCF_DCF!G8/(1+VALUE($B4))^4.5,FCF_DCF!H8/(1+VALUE($B4))^5.5,FCF_DCF!I8/(1+VALUE($B4))^6.5,FCF_DCF!J8/(1+VALUE($B4))^7.5,FCF_DCF!K8/(1+VALUE($B4))^8.5,FCF_DCF!L8/(1+VALUE($B4))^9.5,FCF_DCF!M8/(1+VALUE($B4))^10.5)+(FCF_DCF!M8*(1+VALUE(F$3))/(VALUE($B4)-VALUE(F$3)))/(1+VALUE($B4))^10.5)/1000),"-") -> - | G4: =IFERROR(IF(VALUE($B4)<=VALUE(G$3),"-",(SUM(FCF_DCF!C8/(1+VALUE($B4))^0.5,FCF_DCF!D8/(1+VALUE($B4))^1.5,FCF_DCF!E8/(1+VALUE($B4))^2.5,FCF_DCF!F8/(1+VALUE($B4))^3.5,FCF_DCF!G8/(1+VALUE($B4))^4.5,FCF_DCF!H8/(1+VALUE($B4))^5.5,FCF_DCF!I8/(1+VALUE($B4))^6.5,FCF_DCF!J8/(1+VALUE($B4))^7.5,FCF_DCF!K8/(1+VALUE($B4))^8.5,FCF_DCF!L8/(1+VALUE($B4))^9.5,FCF_DCF!M8/(1+VALUE($B4))^10.5)+(FCF_DCF!M8*(1+VALUE(G$3))/(VALUE($B4)-VALUE(G$3)))/(1+VALUE($B4))^10.5)/1000),"-") -> -
B5: 20.0% | C5: =IFERROR(IF(VALUE($B5)<=VALUE(C$3),"-",(SUM(FCF_DCF!C8/(1+VALUE($B5))^0.5,FCF_DCF!D8/(1+VALUE($B5))^1.5,FCF_DCF!E8/(1+VALUE($B5))^2.5,FCF_DCF!F8/(1+VALUE($B5))^3.5,FCF_DCF!G8/(1+VALUE($B5))^4.5,FCF_DCF!H8/(1+VALUE($B5))^5.5,FCF_DCF!I8/(1+VALUE($B5))^6.5,FCF_DCF!J8/(1+VALUE($B5))^7.5,FCF_DCF!K8/(1+VALUE($B5))^8.5,FCF_DCF!L8/(1+VALUE($B5))^9.5,FCF_DCF!M8/(1+VALUE($B5))^10.5)+(FCF_DCF!M8*(1+VALUE(C$3))/(VALUE($B5)-VALUE(C$3)))/(1+VALUE($B5))^10.5)/1000),"-") -> - | D5: =IFERROR(IF(VALUE($B5)<=VALUE(D$3),"-",(SUM(FCF_DCF!C8/(1+VALUE($B5))^0.5,FCF_DCF!D8/(1+VALUE($B5))^1.5,FCF_DCF!E8/(1+VALUE($B5))^2.5,FCF_DCF!F8/(1+VALUE($B5))^3.5,FCF_DCF!G8/(1+VALUE($B5))^4.5,FCF_DCF!H8/(1+VALUE($B5))^5.5,FCF_DCF!I8/(1+VALUE($B5))^6.5,FCF_DCF!J8/(1+VALUE($B5))^7.5,FCF_DCF!K8/(1+VALUE($B5))^8.5,FCF_DCF!L8/(1+VALUE($B5))^9.5,FCF_DCF!M8/(1+VALUE($B5))^10.5)+(FCF_DCF!M8*(1+VALUE(D$3))/(VALUE($B5)-VALUE(D$3)))/(1+VALUE($B5))^10.5)/1000),"-") -> - | E5: =IFERROR(IF(VALUE($B5)<=VALUE(E$3),"-",(SUM(FCF_DCF!C8/(1+VALUE($B5))^0.5,FCF_DCF!D8/(1+VALUE($B5))^1.5,FCF_DCF!E8/(1+VALUE($B5))^2.5,FCF_DCF!F8/(1+VALUE($B5))^3.5,FCF_DCF!G8/(1+VALUE($B5))^4.5,FCF_DCF!H8/(1+VALUE($B5))^5.5,FCF_DCF!I8/(1+VALUE($B5))^6.5,FCF_DCF!J8/(1+VALUE($B5))^7.5,FCF_DCF!K8/(1+VALUE($B5))^8.5,FCF_DCF!L8/(1+VALUE($B5))^9.5,FCF_DCF!M8/(1+VALUE($B5))^10.5)+(FCF_DCF!M8*(1+VALUE(E$3))/(VALUE($B5)-VALUE(E$3)))/(1+VALUE($B5))^10.5)/1000),"-") -> - | F5: =IFERROR(IF(VALUE($B5)<=VALUE(F$3),"-",(SUM(FCF_DCF!C8/(1+VALUE($B5))^0.5,FCF_DCF!D8/(1+VALUE($B5))^1.5,FCF_DCF!E8/(1+VALUE($B5))^2.5,FCF_DCF!F8/(1+VALUE($B5))^3.5,FCF_DCF!G8/(1+VALUE($B5))^4.5,FCF_DCF!H8/(1+VALUE($B5))^5.5,FCF_DCF!I8/(1+VALUE($B5))^6.5,FCF_DCF!J8/(1+VALUE($B5))^7.5,FCF_DCF!K8/(1+VALUE($B5))^8.5,FCF_DCF!L8/(1+VALUE($B5))^9.5,FCF_DCF!M8/(1+VALUE($B5))^10.5)+(FCF_DCF!M8*(1+VALUE(F$3))/(VALUE($B5)-VALUE(F$3)))/(1+VALUE($B5))^10.5)/1000),"-") -> - | G5: =IFERROR(IF(VALUE($B5)<=VALUE(G$3),"-",(SUM(FCF_DCF!C8/(1+VALUE($B5))^0.5,FCF_DCF!D8/(1+VALUE($B5))^1.5,FCF_DCF!E8/(1+VALUE($B5))^2.5,FCF_DCF!F8/(1+VALUE($B5))^3.5,FCF_DCF!G8/(1+VALUE($B5))^4.5,FCF_DCF!H8/(1+VALUE($B5))^5.5,FCF_DCF!I8/(1+VALUE($B5))^6.5,FCF_DCF!J8/(1+VALUE($B5))^7.5,FCF_DCF!K8/(1+VALUE($B5))^8.5,FCF_DCF!L8/(1+VALUE($B5))^9.5,FCF_DCF!M8/(1+VALUE($B5))^10.5)+(FCF_DCF!M8*(1+VALUE(G$3))/(VALUE($B5)-VALUE(G$3)))/(1+VALUE($B5))^10.5)/1000),"-") -> -
B6: 22.0% | C6: =IFERROR(IF(VALUE($B6)<=VALUE(C$3),"-",(SUM(FCF_DCF!C8/(1+VALUE($B6))^0.5,FCF_DCF!D8/(1+VALUE($B6))^1.5,FCF_DCF!E8/(1+VALUE($B6))^2.5,FCF_DCF!F8/(1+VALUE($B6))^3.5,FCF_DCF!G8/(1+VALUE($B6))^4.5,FCF_DCF!H8/(1+VALUE($B6))^5.5,FCF_DCF!I8/(1+VALUE($B6))^6.5,FCF_DCF!J8/(1+VALUE($B6))^7.5,FCF_DCF!K8/(1+VALUE($B6))^8.5,FCF_DCF!L8/(1+VALUE($B6))^9.5,FCF_DCF!M8/(1+VALUE($B6))^10.5)+(FCF_DCF!M8*(1+VALUE(C$3))/(VALUE($B6)-VALUE(C$3)))/(1+VALUE($B6))^10.5)/1000),"-") -> - | D6: =IFERROR(IF(VALUE($B6)<=VALUE(D$3),"-",(SUM(FCF_DCF!C8/(1+VALUE($B6))^0.5,FCF_DCF!D8/(1+VALUE($B6))^1.5,FCF_DCF!E8/(1+VALUE($B6))^2.5,FCF_DCF!F8/(1+VALUE($B6))^3.5,FCF_DCF!G8/(1+VALUE($B6))^4.5,FCF_DCF!H8/(1+VALUE($B6))^5.5,FCF_DCF!I8/(1+VALUE($B6))^6.5,FCF_DCF!J8/(1+VALUE($B6))^7.5,FCF_DCF!K8/(1+VALUE($B6))^8.5,FCF_DCF!L8/(1+VALUE($B6))^9.5,FCF_DCF!M8/(1+VALUE($B6))^10.5)+(FCF_DCF!M8*(1+VALUE(D$3))/(VALUE($B6)-VALUE(D$3)))/(1+VALUE($B6))^10.5)/1000),"-") -> - | E6: =IFERROR(IF(VALUE($B6)<=VALUE(E$3),"-",(SUM(FCF_DCF!C8/(1+VALUE($B6))^0.5,FCF_DCF!D8/(1+VALUE($B6))^1.5,FCF_DCF!E8/(1+VALUE($B6))^2.5,FCF_DCF!F8/(1+VALUE($B6))^3.5,FCF_DCF!G8/(1+VALUE($B6))^4.5,FCF_DCF!H8/(1+VALUE($B6))^5.5,FCF_DCF!I8/(1+VALUE($B6))^6.5,FCF_DCF!J8/(1+VALUE($B6))^7.5,FCF_DCF!K8/(1+VALUE($B6))^8.5,FCF_DCF!L8/(1+VALUE($B6))^9.5,FCF_DCF!M8/(1+VALUE($B6))^10.5)+(FCF_DCF!M8*(1+VALUE(E$3))/(VALUE($B6)-VALUE(E$3)))/(1+VALUE($B6))^10.5)/1000),"-") -> - | F6: =IFERROR(IF(VALUE($B6)<=VALUE(F$3),"-",(SUM(FCF_DCF!C8/(1+VALUE($B6))^0.5,FCF_DCF!D8/(1+VALUE($B6))^1.5,FCF_DCF!E8/(1+VALUE($B6))^2.5,FCF_DCF!F8/(1+VALUE($B6))^3.5,FCF_DCF!G8/(1+VALUE($B6))^4.5,FCF_DCF!H8/(1+VALUE($B6))^5.5,FCF_DCF!I8/(1+VALUE($B6))^6.5,FCF_DCF!J8/(1+VALUE($B6))^7.5,FCF_DCF!K8/(1+VALUE($B6))^8.5,FCF_DCF!L8/(1+VALUE($B6))^9.5,FCF_DCF!M8/(1+VALUE($B6))^10.5)+(FCF_DCF!M8*(1+VALUE(F$3))/(VALUE($B6)-VALUE(F$3)))/(1+VALUE($B6))^10.5)/1000),"-") -> - | G6: =IFERROR(IF(VALUE($B6)<=VALUE(G$3),"-",(SUM(FCF_DCF!C8/(1+VALUE($B6))^0.5,FCF_DCF!D8/(1+VALUE($B6))^1.5,FCF_DCF!E8/(1+VALUE($B6))^2.5,FCF_DCF!F8/(1+VALUE($B6))^3.5,FCF_DCF!G8/(1+VALUE($B6))^4.5,FCF_DCF!H8/(1+VALUE($B6))^5.5,FCF_DCF!I8/(1+VALUE($B6))^6.5,FCF_DCF!J8/(1+VALUE($B6))^7.5,FCF_DCF!K8/(1+VALUE($B6))^8.5,FCF_DCF!L8/(1+VALUE($B6))^9.5,FCF_DCF!M8/(1+VALUE($B6))^10.5)+(FCF_DCF!M8*(1+VALUE(G$3))/(VALUE($B6)-VALUE(G$3)))/(1+VALUE($B6))^10.5)/1000),"-") -> -
B7: 22.7% | C7: =IFERROR(IF(VALUE($B7)<=VALUE(C$3),"-",(SUM(FCF_DCF!C8/(1+VALUE($B7))^0.5,FCF_DCF!D8/(1+VALUE($B7))^1.5,FCF_DCF!E8/(1+VALUE($B7))^2.5,FCF_DCF!F8/(1+VALUE($B7))^3.5,FCF_DCF!G8/(1+VALUE($B7))^4.5,FCF_DCF!H8/(1+VALUE($B7))^5.5,FCF_DCF!I8/(1+VALUE($B7))^6.5,FCF_DCF!J8/(1+VALUE($B7))^7.5,FCF_DCF!K8/(1+VALUE($B7))^8.5,FCF_DCF!L8/(1+VALUE($B7))^9.5,FCF_DCF!M8/(1+VALUE($B7))^10.5)+(FCF_DCF!M8*(1+VALUE(C$3))/(VALUE($B7)-VALUE(C$3)))/(1+VALUE($B7))^10.5)/1000),"-") -> - | D7: =IFERROR(IF(VALUE($B7)<=VALUE(D$3),"-",(SUM(FCF_DCF!C8/(1+VALUE($B7))^0.5,FCF_DCF!D8/(1+VALUE($B7))^1.5,FCF_DCF!E8/(1+VALUE($B7))^2.5,FCF_DCF!F8/(1+VALUE($B7))^3.5,FCF_DCF!G8/(1+VALUE($B7))^4.5,FCF_DCF!H8/(1+VALUE($B7))^5.5,FCF_DCF!I8/(1+VALUE($B7))^6.5,FCF_DCF!J8/(1+VALUE($B7))^7.5,FCF_DCF!K8/(1+VALUE($B7))^8.5,FCF_DCF!L8/(1+VALUE($B7))^9.5,FCF_DCF!M8/(1+VALUE($B7))^10.5)+(FCF_DCF!M8*(1+VALUE(D$3))/(VALUE($B7)-VALUE(D$3)))/(1+VALUE($B7))^10.5)/1000),"-") -> - | E7: =IFERROR(IF(VALUE($B7)<=VALUE(E$3),"-",(SUM(FCF_DCF!C8/(1+VALUE($B7))^0.5,FCF_DCF!D8/(1+VALUE($B7))^1.5,FCF_DCF!E8/(1+VALUE($B7))^2.5,FCF_DCF!F8/(1+VALUE($B7))^3.5,FCF_DCF!G8/(1+VALUE($B7))^4.5,FCF_DCF!H8/(1+VALUE($B7))^5.5,FCF_DCF!I8/(1+VALUE($B7))^6.5,FCF_DCF!J8/(1+VALUE($B7))^7.5,FCF_DCF!K8/(1+VALUE($B7))^8.5,FCF_DCF!L8/(1+VALUE($B7))^9.5,FCF_DCF!M8/(1+VALUE($B7))^10.5)+(FCF_DCF!M8*(1+VALUE(E$3))/(VALUE($B7)-VALUE(E$3)))/(1+VALUE($B7))^10.5)/1000),"-") -> - | F7: =IFERROR(IF(VALUE($B7)<=VALUE(F$3),"-",(SUM(FCF_DCF!C8/(1+VALUE($B7))^0.5,FCF_DCF!D8/(1+VALUE($B7))^1.5,FCF_DCF!E8/(1+VALUE($B7))^2.5,FCF_DCF!F8/(1+VALUE($B7))^3.5,FCF_DCF!G8/(1+VALUE($B7))^4.5,FCF_DCF!H8/(1+VALUE($B7))^5.5,FCF_DCF!I8/(1+VALUE($B7))^6.5,FCF_DCF!J8/(1+VALUE($B7))^7.5,FCF_DCF!K8/(1+VALUE($B7))^8.5,FCF_DCF!L8/(1+VALUE($B7))^9.5,FCF_DCF!M8/(1+VALUE($B7))^10.5)+(FCF_DCF!M8*(1+VALUE(F$3))/(VALUE($B7)-VALUE(F$3)))/(1+VALUE($B7))^10.5)/1000),"-") -> - | G7: =IFERROR(IF(VALUE($B7)<=VALUE(G$3),"-",(SUM(FCF_DCF!C8/(1+VALUE($B7))^0.5,FCF_DCF!D8/(1+VALUE($B7))^1.5,FCF_DCF!E8/(1+VALUE($B7))^2.5,FCF_DCF!F8/(1+VALUE($B7))^3.5,FCF_DCF!G8/(1+VALUE($B7))^4.5,FCF_DCF!H8/(1+VALUE($B7))^5.5,FCF_DCF!I8/(1+VALUE($B7))^6.5,FCF_DCF!J8/(1+VALUE($B7))^7.5,FCF_DCF!K8/(1+VALUE($B7))^8.5,FCF_DCF!L8/(1+VALUE($B7))^9.5,FCF_DCF!M8/(1+VALUE($B7))^10.5)+(FCF_DCF!M8*(1+VALUE(G$3))/(VALUE($B7)-VALUE(G$3)))/(1+VALUE($B7))^10.5)/1000),"-") -> -
B8: 24.0% | C8: =IFERROR(IF(VALUE($B8)<=VALUE(C$3),"-",(SUM(FCF_DCF!C8/(1+VALUE($B8))^0.5,FCF_DCF!D8/(1+VALUE($B8))^1.5,FCF_DCF!E8/(1+VALUE($B8))^2.5,FCF_DCF!F8/(1+VALUE($B8))^3.5,FCF_DCF!G8/(1+VALUE($B8))^4.5,FCF_DCF!H8/(1+VALUE($B8))^5.5,FCF_DCF!I8/(1+VALUE($B8))^6.5,FCF_DCF!J8/(1+VALUE($B8))^7.5,FCF_DCF!K8/(1+VALUE($B8))^8.5,FCF_DCF!L8/(1+VALUE($B8))^9.5,FCF_DCF!M8/(1+VALUE($B8))^10.5)+(FCF_DCF!M8*(1+VALUE(C$3))/(VALUE($B8)-VALUE(C$3)))/(1+VALUE($B8))^10.5)/1000),"-") -> - | D8: =IFERROR(IF(VALUE($B8)<=VALUE(D$3),"-",(SUM(FCF_DCF!C8/(1+VALUE($B8))^0.5,FCF_DCF!D8/(1+VALUE($B8))^1.5,FCF_DCF!E8/(1+VALUE($B8))^2.5,FCF_DCF!F8/(1+VALUE($B8))^3.5,FCF_DCF!G8/(1+VALUE($B8))^4.5,FCF_DCF!H8/(1+VALUE($B8))^5.5,FCF_DCF!I8/(1+VALUE($B8))^6.5,FCF_DCF!J8/(1+VALUE($B8))^7.5,FCF_DCF!K8/(1+VALUE($B8))^8.5,FCF_DCF!L8/(1+VALUE($B8))^9.5,FCF_DCF!M8/(1+VALUE($B8))^10.5)+(FCF_DCF!M8*(1+VALUE(D$3))/(VALUE($B8)-VALUE(D$3)))/(1+VALUE($B8))^10.5)/1000),"-") -> - | E8: =IFERROR(IF(VALUE($B8)<=VALUE(E$3),"-",(SUM(FCF_DCF!C8/(1+VALUE($B8))^0.5,FCF_DCF!D8/(1+VALUE($B8))^1.5,FCF_DCF!E8/(1+VALUE($B8))^2.5,FCF_DCF!F8/(1+VALUE($B8))^3.5,FCF_DCF!G8/(1+VALUE($B8))^4.5,FCF_DCF!H8/(1+VALUE($B8))^5.5,FCF_DCF!I8/(1+VALUE($B8))^6.5,FCF_DCF!J8/(1+VALUE($B8))^7.5,FCF_DCF!K8/(1+VALUE($B8))^8.5,FCF_DCF!L8/(1+VALUE($B8))^9.5,FCF_DCF!M8/(1+VALUE($B8))^10.5)+(FCF_DCF!M8*(1+VALUE(E$3))/(VALUE($B8)-VALUE(E$3)))/(1+VALUE($B8))^10.5)/1000),"-") -> - | F8: =IFERROR(IF(VALUE($B8)<=VALUE(F$3),"-",(SUM(FCF_DCF!C8/(1+VALUE($B8))^0.5,FCF_DCF!D8/(1+VALUE($B8))^1.5,FCF_DCF!E8/(1+VALUE($B8))^2.5,FCF_DCF!F8/(1+VALUE($B8))^3.5,FCF_DCF!G8/(1+VALUE($B8))^4.5,FCF_DCF!H8/(1+VALUE($B8))^5.5,FCF_DCF!I8/(1+VALUE($B8))^6.5,FCF_DCF!J8/(1+VALUE($B8))^7.5,FCF_DCF!K8/(1+VALUE($B8))^8.5,FCF_DCF!L8/(1+VALUE($B8))^9.5,FCF_DCF!M8/(1+VALUE($B8))^10.5)+(FCF_DCF!M8*(1+VALUE(F$3))/(VALUE($B8)-VALUE(F$3)))/(1+VALUE($B8))^10.5)/1000),"-") -> - | G8: =IFERROR(IF(VALUE($B8)<=VALUE(G$3),"-",(SUM(FCF_DCF!C8/(1+VALUE($B8))^0.5,FCF_DCF!D8/(1+VALUE($B8))^1.5,FCF_DCF!E8/(1+VALUE($B8))^2.5,FCF_DCF!F8/(1+VALUE($B8))^3.5,FCF_DCF!G8/(1+VALUE($B8))^4.5,FCF_DCF!H8/(1+VALUE($B8))^5.5,FCF_DCF!I8/(1+VALUE($B8))^6.5,FCF_DCF!J8/(1+VALUE($B8))^7.5,FCF_DCF!K8/(1+VALUE($B8))^8.5,FCF_DCF!L8/(1+VALUE($B8))^9.5,FCF_DCF!M8/(1+VALUE($B8))^10.5)+(FCF_DCF!M8*(1+VALUE(G$3))/(VALUE($B8)-VALUE(G$3)))/(1+VALUE($B8))^10.5)/1000),"-") -> -
B9: 26.0% | C9: =IFERROR(IF(VALUE($B9)<=VALUE(C$3),"-",(SUM(FCF_DCF!C8/(1+VALUE($B9))^0.5,FCF_DCF!D8/(1+VALUE($B9))^1.5,FCF_DCF!E8/(1+VALUE($B9))^2.5,FCF_DCF!F8/(1+VALUE($B9))^3.5,FCF_DCF!G8/(1+VALUE($B9))^4.5,FCF_DCF!H8/(1+VALUE($B9))^5.5,FCF_DCF!I8/(1+VALUE($B9))^6.5,FCF_DCF!J8/(1+VALUE($B9))^7.5,FCF_DCF!K8/(1+VALUE($B9))^8.5,FCF_DCF!L8/(1+VALUE($B9))^9.5,FCF_DCF!M8/(1+VALUE($B9))^10.5)+(FCF_DCF!M8*(1+VALUE(C$3))/(VALUE($B9)-VALUE(C$3)))/(1+VALUE($B9))^10.5)/1000),"-") -> - | D9: =IFERROR(IF(VALUE($B9)<=VALUE(D$3),"-",(SUM(FCF_DCF!C8/(1+VALUE($B9))^0.5,FCF_DCF!D8/(1+VALUE($B9))^1.5,FCF_DCF!E8/(1+VALUE($B9))^2.5,FCF_DCF!F8/(1+VALUE($B9))^3.5,FCF_DCF!G8/(1+VALUE($B9))^4.5,FCF_DCF!H8/(1+VALUE($B9))^5.5,FCF_DCF!I8/(1+VALUE($B9))^6.5,FCF_DCF!J8/(1+VALUE($B9))^7.5,FCF_DCF!K8/(1+VALUE($B9))^8.5,FCF_DCF!L8/(1+VALUE($B9))^9.5,FCF_DCF!M8/(1+VALUE($B9))^10.5)+(FCF_DCF!M8*(1+VALUE(D$3))/(VALUE($B9)-VALUE(D$3)))/(1+VALUE($B9))^10.5)/1000),"-") -> - | E9: =IFERROR(IF(VALUE($B9)<=VALUE(E$3),"-",(SUM(FCF_DCF!C8/(1+VALUE($B9))^0.5,FCF_DCF!D8/(1+VALUE($B9))^1.5,FCF_DCF!E8/(1+VALUE($B9))^2.5,FCF_DCF!F8/(1+VALUE($B9))^3.5,FCF_DCF!G8/(1+VALUE($B9))^4.5,FCF_DCF!H8/(1+VALUE($B9))^5.5,FCF_DCF!I8/(1+VALUE($B9))^6.5,FCF_DCF!J8/(1+VALUE($B9))^7.5,FCF_DCF!K8/(1+VALUE($B9))^8.5,FCF_DCF!L8/(1+VALUE($B9))^9.5,FCF_DCF!M8/(1+VALUE($B9))^10.5)+(FCF_DCF!M8*(1+VALUE(E$3))/(VALUE($B9)-VALUE(E$3)))/(1+VALUE($B9))^10.5)/1000),"-") -> - | F9: =IFERROR(IF(VALUE($B9)<=VALUE(F$3),"-",(SUM(FCF_DCF!C8/(1+VALUE($B9))^0.5,FCF_DCF!D8/(1+VALUE($B9))^1.5,FCF_DCF!E8/(1+VALUE($B9))^2.5,FCF_DCF!F8/(1+VALUE($B9))^3.5,FCF_DCF!G8/(1+VALUE($B9))^4.5,FCF_DCF!H8/(1+VALUE($B9))^5.5,FCF_DCF!I8/(1+VALUE($B9))^6.5,FCF_DCF!J8/(1+VALUE($B9))^7.5,FCF_DCF!K8/(1+VALUE($B9))^8.5,FCF_DCF!L8/(1+VALUE($B9))^9.5,FCF_DCF!M8/(1+VALUE($B9))^10.5)+(FCF_DCF!M8*(1+VALUE(F$3))/(VALUE($B9)-VALUE(F$3)))/(1+VALUE($B9))^10.5)/1000),"-") -> - | G9: =IFERROR(IF(VALUE($B9)<=VALUE(G$3),"-",(SUM(FCF_DCF!C8/(1+VALUE($B9))^0.5,FCF_DCF!D8/(1+VALUE($B9))^1.5,FCF_DCF!E8/(1+VALUE($B9))^2.5,FCF_DCF!F8/(1+VALUE($B9))^3.5,FCF_DCF!G8/(1+VALUE($B9))^4.5,FCF_DCF!H8/(1+VALUE($B9))^5.5,FCF_DCF!I8/(1+VALUE($B9))^6.5,FCF_DCF!J8/(1+VALUE($B9))^7.5,FCF_DCF!K8/(1+VALUE($B9))^8.5,FCF_DCF!L8/(1+VALUE($B9))^9.5,FCF_DCF!M8/(1+VALUE($B9))^10.5)+(FCF_DCF!M8*(1+VALUE(G$3))/(VALUE($B9)-VALUE(G$3)))/(1+VALUE($B9))^10.5)/1000),"-") -> -
B10: 28.0% | C10: =IFERROR(IF(VALUE($B10)<=VALUE(C$3),"-",(SUM(FCF_DCF!C8/(1+VALUE($B10))^0.5,FCF_DCF!D8/(1+VALUE($B10))^1.5,FCF_DCF!E8/(1+VALUE($B10))^2.5,FCF_DCF!F8/(1+VALUE($B10))^3.5,FCF_DCF!G8/(1+VALUE($B10))^4.5,FCF_DCF!H8/(1+VALUE($B10))^5.5,FCF_DCF!I8/(1+VALUE($B10))^6.5,FCF_DCF!J8/(1+VALUE($B10))^7.5,FCF_DCF!K8/(1+VALUE($B10))^8.5,FCF_DCF!L8/(1+VALUE($B10))^9.5,FCF_DCF!M8/(1+VALUE($B10))^10.5)+(FCF_DCF!M8*(1+VALUE(C$3))/(VALUE($B10)-VALUE(C$3)))/(1+VALUE($B10))^10.5)/1000),"-") -> - | D10: =IFERROR(IF(VALUE($B10)<=VALUE(D$3),"-",(SUM(FCF_DCF!C8/(1+VALUE($B10))^0.5,FCF_DCF!D8/(1+VALUE($B10))^1.5,FCF_DCF!E8/(1+VALUE($B10))^2.5,FCF_DCF!F8/(1+VALUE($B10))^3.5,FCF_DCF!G8/(1+VALUE($B10))^4.5,FCF_DCF!H8/(1+VALUE($B10))^5.5,FCF_DCF!I8/(1+VALUE($B10))^6.5,FCF_DCF!J8/(1+VALUE($B10))^7.5,FCF_DCF!K8/(1+VALUE($B10))^8.5,FCF_DCF!L8/(1+VALUE($B10))^9.5,FCF_DCF!M8/(1+VALUE($B10))^10.5)+(FCF_DCF!M8*(1+VALUE(D$3))/(VALUE($B10)-VALUE(D$3)))/(1+VALUE($B10))^10.5)/1000),"-") -> - | E10: =IFERROR(IF(VALUE($B10)<=VALUE(E$3),"-",(SUM(FCF_DCF!C8/(1+VALUE($B10))^0.5,FCF_DCF!D8/(1+VALUE($B10))^1.5,FCF_DCF!E8/(1+VALUE($B10))^2.5,FCF_DCF!F8/(1+VALUE($B10))^3.5,FCF_DCF!G8/(1+VALUE($B10))^4.5,FCF_DCF!H8/(1+VALUE($B10))^5.5,FCF_DCF!I8/(1+VALUE($B10))^6.5,FCF_DCF!J8/(1+VALUE($B10))^7.5,FCF_DCF!K8/(1+VALUE($B10))^8.5,FCF_DCF!L8/(1+VALUE($B10))^9.5,FCF_DCF!M8/(1+VALUE($B10))^10.5)+(FCF_DCF!M8*(1+VALUE(E$3))/(VALUE($B10)-VALUE(E$3)))/(1+VALUE($B10))^10.5)/1000),"-") -> - | F10: =IFERROR(IF(VALUE($B10)<=VALUE(F$3),"-",(SUM(FCF_DCF!C8/(1+VALUE($B10))^0.5,FCF_DCF!D8/(1+VALUE($B10))^1.5,FCF_DCF!E8/(1+VALUE($B10))^2.5,FCF_DCF!F8/(1+VALUE($B10))^3.5,FCF_DCF!G8/(1+VALUE($B10))^4.5,FCF_DCF!H8/(1+VALUE($B10))^5.5,FCF_DCF!I8/(1+VALUE($B10))^6.5,FCF_DCF!J8/(1+VALUE($B10))^7.5,FCF_DCF!K8/(1+VALUE($B10))^8.5,FCF_DCF!L8/(1+VALUE($B10))^9.5,FCF_DCF!M8/(1+VALUE($B10))^10.5)+(FCF_DCF!M8*(1+VALUE(F$3))/(VALUE($B10)-VALUE(F$3)))/(1+VALUE($B10))^10.5)/1000),"-") -> - | G10: =IFERROR(IF(VALUE($B10)<=VALUE(G$3),"-",(SUM(FCF_DCF!C8/(1+VALUE($B10))^0.5,FCF_DCF!D8/(1+VALUE($B10))^1.5,FCF_DCF!E8/(1+VALUE($B10))^2.5,FCF_DCF!F8/(1+VALUE($B10))^3.5,FCF_DCF!G8/(1+VALUE($B10))^4.5,FCF_DCF!H8/(1+VALUE($B10))^5.5,FCF_DCF!I8/(1+VALUE($B10))^6.5,FCF_DCF!J8/(1+VALUE($B10))^7.5,FCF_DCF!K8/(1+VALUE($B10))^8.5,FCF_DCF!L8/(1+VALUE($B10))^9.5,FCF_DCF!M8/(1+VALUE($B10))^10.5)+(FCF_DCF!M8*(1+VALUE(G$3))/(VALUE($B10)-VALUE(G$3)))/(1+VALUE($B10))^10.5)/1000),"-") -> -
B12: ℹ️ Formulas compute EV (CHF '000) inline: Σ PV(FCFF) + PV(TV·GGM), with WACC from row header & g from column header. No Data Table needed.

Sheet Dashboard
B1: [COMPANY NAME] | INVESTOR DCF DASHBOARD
B4: [Technology / Product] | [Business Model] | Projection Period: [YYYY]–[YYYY] | Valuation Date: [Date]
B6: 📊 VALUATION SUMMARY
B7: Enterprise Value (CHF) | F7: Equity Value (CHF) | J7: WACC (Base Case)
B8: =IFERROR(FCF_DCF!C20,"-") -> - | F8: =IFERROR(FCF_DCF!C22,"-") -> - | J8: =Assumptions!C11 -> 0
B10: Base Case DCF — GGM Terminal Value | F10: EV less net financial debt | J10: CAPM bottom-up
B12: 💰 REVENUE & PROFITABILITY HIGHLIGHTS
B13: Peak Revenue 2035 (CHF) | F13: Peak EBITDA 2035 (CHF) | J13: EBITDA Margin 2035
B14: =Revenue!M11 -> 0 | F14: =PnL_OPEX!M15 -> 0 | J14: =PnL_OPEX!M16 -> -
B16: Total licensing + royalties + co-dev | F16: After all operating costs | J16: High-margin asset-light model
B18: ⚙️ KEY ASSUMPTIONS SNAPSHOT
B19: Terminal Growth Rate (g) | F19: EV/EBITDA Cross-Check | J19: Deal 1 Royalty Rate
B20: =Assumptions!C49 -> 0 | F20: =IFERROR(FCF_DCF!C20/PnL_OPEX!M15,"-") -> - | J20: =Assumptions!C17 -> 0
B22: Long-run nominal GDP aligned | F22: vs. comp set median 12x | J22: Deal 1 royalty rate
B24: 📈 REVENUE FORECAST BY YEAR (CHF)
B25: Year | C25: Deal 1 | D25: Deal 2 | E25: Deals 3-6 | F25: Total Revenue | G25: YoY Growth
B26: 2025 | C26: =Revenue!C4 -> 0 | D26: =Revenue!C5 -> 0 | E26: =IFERROR(Revenue!C11-Revenue!C4-Revenue!C5,0) -> 0 | F26: =Revenue!C11 -> 0 | G26: -
B27: 2026 | C27: =Revenue!D4 -> 0 | D27: =Revenue!D5 -> 0 | E27: =IFERROR(Revenue!D11-Revenue!D4-Revenue!D5,0) -> 0 | F27: =Revenue!D11 -> 0 | G27: =IFERROR((Revenue!D11-Revenue!C11)/Revenue!C11,"-") -> -
B28: 2027 | C28: =Revenue!E4 -> 0 | D28: =Revenue!E5 -> 0 | E28: =IFERROR(Revenue!E11-Revenue!E4-Revenue!E5,0) -> 0 | F28: =Revenue!E11 -> 0 | G28: =IFERROR((Revenue!E11-Revenue!D11)/Revenue!D11,"-") -> -
B29: 2028 | C29: =Revenue!F4 -> 0 | D29: =Revenue!F5 -> 0 | E29: =IFERROR(Revenue!F11-Revenue!F4-Revenue!F5,0) -> 0 | F29: =Revenue!F11 -> 0 | G29: =IFERROR((Revenue!F11-Revenue!E11)/Revenue!E11,"-") -> -
B30: 2029 | C30: =Revenue!G4 -> 0 | D30: =Revenue!G5 -> 0 | E30: =IFERROR(Revenue!G11-Revenue!G4-Revenue!G5,0) -> 0 | F30: =Revenue!G11 -> 0 | G30: =IFERROR((Revenue!G11-Revenue!F11)/Revenue!F11,"-") -> -
B31: 2030 | C31: =Revenue!H4 -> 0 | D31: =Revenue!H5 -> 0 | E31: =IFERROR(Revenue!H11-Revenue!H4-Revenue!H5,0) -> 0 | F31: =Revenue!H11 -> 0 | G31: =IFERROR((Revenue!H11-Revenue!G11)/Revenue!G11,"-") -> -
B32: 2031 | C32: =Revenue!I4 -> 0 | D32: =Revenue!I5 -> 0 | E32: =IFERROR(Revenue!I11-Revenue!I4-Revenue!I5,0) -> 0 | F32: =Revenue!I11 -> 0 | G32: =IFERROR((Revenue!I11-Revenue!H11)/Revenue!H11,"-") -> -
B33: 2032 | C33: =Revenue!J4 -> 0 | D33: =Revenue!J5 -> 0 | E33: =IFERROR(Revenue!J11-Revenue!J4-Revenue!J5,0) -> 0 | F33: =Revenue!J11 -> 0 | G33: =IFERROR((Revenue!J11-Revenue!I11)/Revenue!I11,"-") -> -
B34: 2033 | C34: =Revenue!K4 -> 0 | D34: =Revenue!K5 -> 0 | E34: =IFERROR(Revenue!K11-Revenue!K4-Revenue!K5,0) -> 0 | F34: =Revenue!K11 -> 0 | G34: =IFERROR((Revenue!K11-Revenue!J11)/Revenue!J11,"-") -> -
B35: 2034 | C35: =Revenue!L4 -> 0 | D35: =Revenue!L5 -> 0 | E35: =IFERROR(Revenue!L11-Revenue!L4-Revenue!L5,0) -> 0 | F35: =Revenue!L11 -> 0 | G35: =IFERROR((Revenue!L11-Revenue!K11)/Revenue!K11,"-") -> -
B36: 2035 | C36: =Revenue!M4 -> 0 | D36: =Revenue!M5 -> 0 | E36: =IFERROR(Revenue!M11-Revenue!M4-Revenue!M5,0) -> 0 | F36: =Revenue!M11 -> 0 | G36: =IFERROR((Revenue!M11-Revenue!L11)/Revenue!L11,"-") -> -
B38: 📋 P&L SUMMARY (CHF) — KEY YEARS
B39: Metric | C39: 2025 | D39: 2027 | E39: 2029 | F39: 2032 | G39: 2035
B40: Total Revenue | C40: =Revenue!C11 -> 0 | D40: =Revenue!E11 -> 0 | E40: =Revenue!G11 -> 0 | F40: =Revenue!J11 -> 0 | G40: =Revenue!M11 -> 0
B41: Total OPEX | C41: =PnL_OPEX!C12 -> 0 | D41: =PnL_OPEX!E12 -> 0 | E41: =PnL_OPEX!G12 -> 0 | F41: =PnL_OPEX!J12 -> 0 | G41: =PnL_OPEX!M12 -> 0
B42: EBITDA | C42: =PnL_OPEX!C15 -> 0 | D42: =PnL_OPEX!E15 -> 0 | E42: =PnL_OPEX!G15 -> 0 | F42: =PnL_OPEX!J15 -> 0 | G42: =PnL_OPEX!M15 -> 0
B43: EBITDA Margin % | C43: =PnL_OPEX!C16 -> - | D43: =PnL_OPEX!E16 -> - | E43: =PnL_OPEX!G16 -> - | F43: =PnL_OPEX!J16 -> - | G43: =PnL_OPEX!M16 -> -
B44: D&A | C44: =PnL_OPEX!C19 -> 0 | D44: =PnL_OPEX!E19 -> 0 | E44: =PnL_OPEX!G19 -> 0 | F44: =PnL_OPEX!J19 -> 0 | G44: =PnL_OPEX!M19 -> 0
B45: EBIT | C45: =PnL_OPEX!C20 -> 0 | D45: =PnL_OPEX!E20 -> 0 | E45: =PnL_OPEX!G20 -> 0 | F45: =PnL_OPEX!J20 -> 0 | G45: =PnL_OPEX!M20 -> 0
B46: NOPAT | C46: =PnL_OPEX!C22 -> 0 | D46: =PnL_OPEX!E22 -> 0 | E46: =PnL_OPEX!G22 -> 0 | F46: =PnL_OPEX!J22 -> 0 | G46: =PnL_OPEX!M22 -> 0
B48: 🎯 SCENARIO ANALYSIS — BEAR / BASE / BULL
B49: Parameter | C49: Bear | D49: Base (Model) | E49: Bull
B50: Royalty Rate — Deal 1
B51: Co-Dev Fee — Deal 2
...
